output/results/trades.txt
Matched Trades
Order{id=38040, symbol='AAPL', side='sell', type='market', price=null, timeStamp=1608936605}
Order{id=37911, symbol='AAPL', side='buy', type='limit', price=130.97, timeStamp=1608936540}

Order{id=19632, symbol='TSLA', side='sell', type='limit', price=658.2, timeStamp=1608927330}
Order{id=19623, symbol='TSLA', side='buy', type='limit', price=659.46, timeStamp=1608927324}

Order{id=19764, symbol='AMZN', side='sell', type='limit', price=3171.05, timeStamp=1608927396}
Order{id=19713, symbol='AMZN', side='buy', type='limit', price=3171.08, timeStamp=1608927372}

Order{id=6438, symbol='AAPL', side='sell', type='market', price=null, timeStamp=1608920656}
Order{id=6394, symbol='AAPL', side='buy', type='limit', price=130.9, timeStamp=1608920635}

Order{id=41175, symbol='AMZN', side='sell', type='market', price=null, timeStamp=1608938172}
Order{id=41156, symbol='AMZN', side='buy', type='limit', price=3170.21, timeStamp=1608938162}

Order{id=13214, symbol='AMZN', side='sell', type='market', price=null, timeStamp=1608924066}
Order{id=13211, symbol='AMZN', side='buy', type='limit', price=3171.46, timeStamp=1608924064}

Order{id=19860, symbol='AMZN', side='buy', type='market', price=3170.33, timeStamp=1608927444}
Order{id=19840, symbol='AMZN', side='sell', type='limit', price=3170.23, timeStamp=1608927434}

Order{id=45796, symbol='TSLA', side='buy', type='limit', price=659.59, timeStamp=1608940488}
Order{id=45795, symbol='TSLA', side='sell', type='limit', price=658.44, timeStamp=1608940488}

Order{id=10044, symbol='AAPL', side='buy', type='limit', price=131.65, timeStamp=1608922475}
Order{id=10033, symbol='AAPL', side='sell', type='limit', price=131.14, timeStamp=1608922469}

Order{id=11105, symbol='AMZN', side='sell', type='market', price=null, timeStamp=1608923018}
Order{id=11071, symbol='AMZN', side='buy', type='limit', price=3170.73, timeStamp=1608923002}

Order{id=2038, symbol='AMZN', side='buy', type='market', price=null, timeStamp=1608918436}
Order{id=2024, symbol='AMZN', side='sell', type='limit', price=3171.77, timeStamp=1608918429}

Order{id=28244, symbol='TSLA', side='sell', type='market', price=null, timeStamp=1608931688}
Order{id=28225, symbol='TSLA', side='buy', type='limit', price=658.13, timeStamp=1608931679}

Order{id=30226, symbol='TSLA', side='buy', type='market', price=null, timeStamp=1608932677}
Order{id=30201, symbol='TSLA', side='sell', type='limit', price=659.87, timeStamp=1608932666}

Order{id=33512, symbol='TSLA', side='sell', type='market', price=null, timeStamp=1608934348}
Order{id=33500, symbol='TSLA', side='buy', type='limit', price=659.17, timeStamp=1608934341}

Order{id=43604, symbol='AAPL', side='sell', type='market', price=null, timeStamp=1608939394}
Order{id=43600, symbol='AAPL', side='buy', type='limit', price=130.75, timeStamp=1608939392}

Order{id=18778, symbol='TSLA', side='sell', type='market', price=null, timeStamp=1608926904}
Order{id=18777, symbol='TSLA', side='buy', type='limit', price=659.09, timeStamp=1608926904}

Order{id=25866, symbol='AMZN', side='buy', type='limit', price=3171.83, timeStamp=1608930503}
Order{id=25828, symbol='AMZN', side='sell', type='limit', price=3171.45, timeStamp=1608930483}

Order{id=35465, symbol='AAPL', side='sell', type='limit', price=130.13, timeStamp=1608935319}
Order{id=35445, symbol='AAPL', side='buy', type='limit', price=131.74, timeStamp=1608935310}

Order{id=27167, symbol='TSLA', side='buy', type='market', price=null, timeStamp=1608931148}
Order{id=27162, symbol='TSLA', side='sell', type='limit', price=659.11, timeStamp=1608931145}

Order{id=40257, symbol='AAPL', side='sell', type='limit', price=130.55, timeStamp=1608937708}
Order{id=40251, symbol='AAPL', side='buy', type='limit', price=131.03, timeStamp=1608937705}

Order{id=35535, symbol='TSLA', side='sell', type='market', price=null, timeStamp=1608935356}
Order{id=35446, symbol='TSLA', side='buy', type='limit', price=658.07, timeStamp=1608935310}

Order{id=25910, symbol='TSLA', side='buy', type='market', price=null, timeStamp=1608930525}
Order{id=25905, symbol='TSLA', side='sell', type='limit', price=658.44, timeStamp=1608930522}

Order{id=30980, symbol='AAPL', side='sell', type='market', price=null, timeStamp=1608933063}
Order{id=30969, symbol='AAPL', side='buy', type='limit', price=130.12, timeStamp=1608933056}

Order{id=18696, symbol='TSLA', side='sell', type='market', price=null, timeStamp=1608926862}
Order{id=18694, symbol='TSLA', side='buy', type='limit', price=659.57, timeStamp=1608926862}

Order{id=34160, symbol='AMZN', side='sell', type='limit', price=3170.8, timeStamp=1608934674}
Order{id=34129, symbol='AMZN', side='buy', type='limit', price=3171.02, timeStamp=1608934661}

Order{id=14928, symbol='TSLA', side='sell', type='market', price=null, timeStamp=1608924921}
Order{id=14923, symbol='TSLA', side='buy', type='limit', price=659.28, timeStamp=1608924919}

Order{id=3407, symbol='AMZN', side='sell', type='limit', price=3170.63, timeStamp=1608919133}
Order{id=3405, symbol='AMZN', side='buy', type='limit', price=3170.84, timeStamp=1608919133}

Order{id=45820, symbol='AAPL', side='sell', type='market', price=null, timeStamp=1608940499}
Order{id=45734, symbol='AAPL', side='buy', type='limit', price=130.07, timeStamp=1608940460}

Order{id=5973, symbol='TSLA', side='buy', type='market', price=null, timeStamp=1608920423}
Order{id=5958, symbol='TSLA', side='sell', type='limit', price=659.7, timeStamp=1608920413}

Order{id=2030, symbol='TSLA', side='buy', type='limit', price=659.28, timeStamp=1608918432}
Order{id=2028, symbol='TSLA', side='sell', type='limit', price=659.08, timeStamp=1608918431}

Order{id=6497, symbol='AAPL', side='buy', type='market', price=null, timeStamp=1608920686}
Order{id=6493, symbol='AAPL', side='sell', type='limit', price=131.77, timeStamp=1608920684}

Order{id=42211, symbol='AAPL', side='sell', type='market', price=null, timeStamp=1608938699}
Order{id=42182, symbol='AAPL', side='buy', type='limit', price=131.02, timeStamp=1608938685}

Order{id=9457, symbol='AAPL', side='buy', type='market', price=null, timeStamp=1608922178}
Order{id=9439, symbol='AAPL', side='sell', type='limit', price=131.08, timeStamp=1608922168}

Order{id=28312, symbol='TSLA', side='sell', type='limit', price=658.93, timeStamp=1608931717}
Order{id=28309, symbol='TSLA', side='buy', type='limit', price=659.73, timeStamp=1608931716}

Order{id=34517, symbol='TSLA', side='buy', type='limit', price=659.86, timeStamp=1608934856}
Order{id=34462, symbol='TSLA', side='sell', type='limit', price=658.88, timeStamp=1608934830}

Order{id=1262, symbol='TSLA', side='buy', type='market', price=659.91, timeStamp=1608918035}
Order{id=1261, symbol='TSLA', side='sell', type='limit', price=659.56, timeStamp=1608918034}

Order{id=27603, symbol='TSLA', side='sell', type='market', price=null, timeStamp=1608931366}
Order{id=27596, symbol='TSLA', side='buy', type='limit', price=659.08, timeStamp=1608931363}

Order{id=26161, symbol='AMZN', side='buy', type='limit', price=3171.85, timeStamp=1608930645}
Order{id=26137, symbol='AMZN', side='sell', type='limit', price=3170.81, timeStamp=1608930634}

Order{id=41507, symbol='AAPL', side='sell', type='market', price=null, timeStamp=1608938341}
Order{id=41497, symbol='AAPL', side='buy', type='limit', price=130.32, timeStamp=1608938336}

Order{id=25967, symbol='TSLA', side='buy', type='limit', price=659.91, timeStamp=1608930549}
Order{id=25864, symbol='TSLA', side='sell', type='limit', price=659.59, timeStamp=1608930502}

Order{id=42357, symbol='AAPL', side='sell', type='market', price=null, timeStamp=1608938769}
Order{id=42352, symbol='AAPL', side='buy', type='limit', price=131.55, timeStamp=1608938767}

Order{id=26709, symbol='AAPL', side='sell', type='market', price=null, timeStamp=1608930910}
Order{id=26572, symbol='AAPL', side='buy', type='limit', price=130.28, timeStamp=1608930845}

Order{id=4554, symbol='AMZN', side='sell', type='market', price=null, timeStamp=1608919719}
Order{id=4553, symbol='AMZN', side='buy', type='limit', price=3170.52, timeStamp=1608919719}
